{   
    "registryname": "Mana",
	"localizedname": "魔法转化机",
	"requires-blueprint": true,
	"color": "19EC8A",
    "parts": [
        {
            "x": -1,
            "y": 0,
            "z": 0,
            "elements": "casings_all"
        },
        {
            "x": 0,
            "y": 0,
            "z": 0,
            "elements": [
                "modularmachinery:blockcontroller@2"
            ]
        },
        {
            "x": 1,
            "y": 2,
            "z": 1,
            "elements": [
                "botania:pool@3"
            ]
        },
        {
            "x": -2,
            "y": 0,
            "z": 0,
            "elements": "casings_all"
        },
        {
            "x": 1,
            "y": 0,
            "z": 0,
            "elements": "casings_all"
        },
        {
            "x": 2,
            "y": 2,
            "z": 1,
            "elements": [
                "gugu-utils:sparkmanahatch@1"
            ]
        },
        {
            "x": 2,
            "y": 0,
            "z": 0,
            "elements": "casings_all"
        },
        {
            "x": -2,
            "y": 0,
            "z": 4,
            "elements": "casings_all"
        },
        {
            "x": -1,
            "y": 0,
            "z": 4,
            "elements": "casings_all"
        },
        {
            "x": 0,
            "y": 0,
            "z": 4,
            "elements": "casings_all"
        },
        {
            "x": 1,
            "y": 0,
            "z": 4,
            "elements": "casings_all"
        },
        {
            "x": 2,
            "y": 0,
            "z": 4,
            "elements": "casings_all"
        },
        {
            "x": 2,
            "y": -1,
            "z": 0,
            "elements": [
                "botania:storage@4"
            ]
        },
        {
            "x": 1,
            "y": -1,
            "z": 0,
            "elements": [
                "botania:storage@4"
            ]
        },
        {
            "x": -2,
            "y": 1,
            "z": 0,
            "elements": [
                "botania:storage@3"
            ]
        },
        {
            "x": -1,
            "y": 3,
            "z": 1,
            "elements": [
                "gugu-utils:sparkmanahatch@1"
            ]
        },
        {
            "x": 0,
            "y": -1,
            "z": 0,
            "elements": [
                "botania:storage@4"
            ]
        },
        {
            "x": -1,
            "y": 1,
            "z": 0,
            "elements": [
                "botania:storage@3"
            ]
        },
        {
            "x": 0,
            "y": 3,
            "z": 1,
            "elements": [
                "gugu-utils:sparkmanahatch@1"
            ]
        },
        {
            "x": -1,
            "y": -1,
            "z": 0,
            "elements": [
                "botania:storage@4"
            ]
        },
        {
            "x": 0,
            "y": 1,
            "z": 0,
            "elements": [
                "botania:storage@3"
            ]
        },
        {
            "x": 1,
            "y": 3,
            "z": 1,
            "elements": [
                "gugu-utils:sparkmanahatch@1"
            ]
        },
        {
            "x": -2,
            "y": -1,
            "z": 0,
            "elements": [
                "botania:storage@4"
            ]
        },
        {
            "x": 1,
            "y": 1,
            "z": 0,
            "elements": [
                "botania:storage@3"
            ]
        },
        {
            "x": 2,
            "y": 1,
            "z": 0,
            "elements": [
                "botania:storage@3"
            ]
        },
        {
            "x": -2,
            "y": 1,
            "z": 4,
            "elements": [
                "botania:storage@3"
            ]
        },
        {
            "x": -2,
            "y": -1,
            "z": 3,
            "elements": [
                "botania:storage@4"
            ]
        },
        {
            "x": -1,
            "y": 1,
            "z": 4,
            "elements": [
                "botania:storage@3"
            ]
        },
        {
            "x": -1,
            "y": -1,
            "z": 3,
            "elements": [
                "botania:altgrass@1"
            ]
        },
        {
            "x": 0,
            "y": 1,
            "z": 4,
            "elements": [
                "botania:storage@3"
            ]
        },
        {
            "x": 0,
            "y": -1,
            "z": 3,
            "elements": [
                "botania:altgrass@1"
            ]
        },
        {
            "x": 1,
            "y": 1,
            "z": 4,
            "elements": [
                "botania:storage@3"
            ]
        },
        {
            "x": 1,
            "y": -1,
            "z": 3,
            "elements": [
                "botania:altgrass@1"
            ]
        },
        {
            "x": 2,
            "y": 1,
            "z": 4,
            "elements": [
                "botania:storage@3"
            ]
        },
        {
            "x": 2,
            "y": -1,
            "z": 3,
            "elements": [
                "botania:storage@4"
            ]
        },
        {
            "x": -2,
            "y": 2,
            "z": 0,
            "elements": [
                "gugu-utils:sparkmanahatch@1"
            ]
        },
        {
            "x": -1,
            "y": 2,
            "z": 0,
            "elements": [
                "gugu-utils:sparkmanahatch@1"
            ]
        },
        {
            "x": 0,
            "y": 2,
            "z": 0,
            "elements": [
                "gugu-utils:sparkmanahatch@1"
            ]
        },
        {
            "x": 1,
            "y": 2,
            "z": 0,
            "elements": [
                "gugu-utils:sparkmanahatch@1"
            ]
        },
        {
            "x": 2,
            "y": 2,
            "z": 0,
            "elements": [
                "gugu-utils:sparkmanahatch@1"
            ]
        },
        {
            "x": -2,
            "y": 2,
            "z": 4,
            "elements": [
                "gugu-utils:sparkmanahatch@1"
            ]
        },
        {
            "x": -2,
            "y": 0,
            "z": 3,
            "elements": "casings_all"
        },
        {
            "x": -1,
            "y": 2,
            "z": 4,
            "elements": [
                "gugu-utils:sparkmanahatch@1"
            ]
        },
        {
            "x": -1,
            "y": 0,
            "z": 3,
            "elements": [
                "botania:pool@3"
            ]
        },
        {
            "x": 0,
            "y": 2,
            "z": 4,
            "elements": [
                "gugu-utils:sparkmanahatch@1"
            ]
        },
        {
            "x": 0,
            "y": 0,
            "z": 3,
            "elements": [
                "botania:pool@3"
            ]
        },
        {
            "x": 1,
            "y": 2,
            "z": 4,
            "elements": [
                "gugu-utils:sparkmanahatch@1"
            ]
        },
        {
            "x": 1,
            "y": 0,
            "z": 3,
            "elements": [
                "botania:pool@3"
            ]
        },
        {
            "x": 2,
            "y": 2,
            "z": 4,
            "elements": [
                "gugu-utils:sparkmanahatch@1"
            ]
        },
        {
            "x": 2,
            "y": 0,
            "z": 3,
            "elements": "casings_all"
        },
        {
            "x": -2,
            "y": 1,
            "z": 3,
            "elements": [
                "botania:storage@3"
            ]
        },
        {
            "x": -2,
            "y": -1,
            "z": 2,
            "elements": [
                "botania:storage@4"
            ]
        },
        {
            "x": -1,
            "y": 1,
            "z": 3,
            "elements": [
                "botania:altgrass@1"
            ]
        },
        {
            "x": -1,
            "y": -1,
            "z": 2,
            "elements": [
                "botania:altgrass@1"
            ]
        },
        {
            "x": 0,
            "y": 1,
            "z": 3,
            "elements": [
                "botania:altgrass@1"
            ]
        },
        {
            "x": 0,
            "y": -1,
            "z": 2,
            "elements": [
                "botania:altgrass@1"
            ]
        },
        {
            "x": 1,
            "y": 1,
            "z": 3,
            "elements": [
                "botania:altgrass@1"
            ]
        },
        {
            "x": 1,
            "y": -1,
            "z": 2,
            "elements": [
                "botania:altgrass@1"
            ]
        },
        {
            "x": 2,
            "y": 1,
            "z": 3,
            "elements": [
                "botania:storage@3"
            ]
        },
        {
            "x": 2,
            "y": -1,
            "z": 2,
            "elements": [
                "botania:storage@4"
            ]
        },
        {
            "x": -2,
            "y": 2,
            "z": 3,
            "elements": [
                "gugu-utils:sparkmanahatch@1"
            ]
        },
        {
            "x": -2,
            "y": 0,
            "z": 2,
            "elements": "casings_all"
        },
        {
            "x": -1,
            "y": 2,
            "z": 3,
            "elements": [
                "botania:pool@3"
            ]
        },
        {
            "x": -1,
            "y": 0,
            "z": 2,
            "elements": [
                "botania:pool@3"
            ]
        },
        {
            "x": 0,
            "y": 2,
            "z": 3,
            "elements": [
                "botania:pool@3"
            ]
        },
        {
            "x": 0,
            "y": 0,
            "z": 2,
            "elements": [
                "botania:pool@3"
            ]
        },
        {
            "x": 1,
            "y": 2,
            "z": 3,
            "elements": [
                "botania:pool@3"
            ]
        },
        {
            "x": 1,
            "y": 0,
            "z": 2,
            "elements": [
                "botania:pool@3"
            ]
        },
        {
            "x": 2,
            "y": 2,
            "z": 3,
            "elements": [
                "gugu-utils:sparkmanahatch@1"
            ]
        },
        {
            "x": 2,
            "y": 0,
            "z": 2,
            "elements": "casings_all"
        },
        {
            "x": -2,
            "y": 1,
            "z": 2,
            "elements": [
                "botania:storage@3"
            ]
        },
        {
            "x": -1,
            "y": 3,
            "z": 3,
            "elements": [
                "gugu-utils:sparkmanahatch@1"
            ]
        },
        {
            "x": -2,
            "y": -1,
            "z": 1,
            "elements": [
                "botania:storage@4"
            ]
        },
        {
            "x": -1,
            "y": 1,
            "z": 2,
            "elements": [
                "botania:altgrass@1"
            ]
        },
        {
            "x": 0,
            "y": 3,
            "z": 3,
            "elements": [
                "gugu-utils:sparkmanahatch@1"
            ]
        },
        {
            "x": -1,
            "y": -1,
            "z": 1,
            "elements": [
                "botania:altgrass@1"
            ]
        },
        {
            "x": 0,
            "y": 1,
            "z": 2,
            "elements": [
                "botania:altgrass@1"
            ]
        },
        {
            "x": 1,
            "y": 3,
            "z": 3,
            "elements": [
                "gugu-utils:sparkmanahatch@1"
            ]
        },
        {
            "x": 0,
            "y": -1,
            "z": 1,
            "elements": [
                "botania:altgrass@1"
            ]
        },
        {
            "x": 1,
            "y": 1,
            "z": 2,
            "elements": [
                "botania:altgrass@1"
            ]
        },
        {
            "x": 1,
            "y": -1,
            "z": 1,
            "elements": [
                "botania:altgrass@1"
            ]
        },
        {
            "x": 2,
            "y": 1,
            "z": 2,
            "elements": [
                "botania:storage@3"
            ]
        },
        {
            "x": 2,
            "y": -1,
            "z": 1,
            "elements": [
                "botania:storage@4"
            ]
        },
        {
            "x": -2,
            "y": 2,
            "z": 2,
            "elements": [
                "gugu-utils:sparkmanahatch@1"
            ]
        },
        {
            "x": -2,
            "y": 0,
            "z": 1,
            "elements": "casings_all"
        },
        {
            "x": -1,
            "y": 2,
            "z": 2,
            "elements": [
                "botania:pool@3"
            ]
        },
        {
            "x": -1,
            "y": 0,
            "z": 1,
            "elements": [
                "botania:pool@3"
            ]
        },
        {
            "x": 0,
            "y": 2,
            "z": 2,
            "elements": [
                "botania:pool@3"
            ]
        },
        {
            "x": 0,
            "y": 0,
            "z": 1,
            "elements": [
                "botania:pool@3"
            ]
        },
        {
            "x": 1,
            "y": 2,
            "z": 2,
            "elements": [
                "botania:pool@3"
            ]
        },
        {
            "x": 1,
            "y": 0,
            "z": 1,
            "elements": [
                "botania:pool@3"
            ]
        },
        {
            "x": 2,
            "y": 2,
            "z": 2,
            "elements": [
                "gugu-utils:sparkmanahatch@1"
            ]
        },
        {
            "x": 2,
            "y": 0,
            "z": 1,
            "elements": "casings_all"
        },
        {
            "x": -2,
            "y": 1,
            "z": 1,
            "elements": [
                "botania:storage@3"
            ]
        },
        {
            "x": -1,
            "y": 3,
            "z": 2,
            "elements": [
                "gugu-utils:sparkmanahatch@1"
            ]
        },
        {
            "x": -1,
            "y": 1,
            "z": 1,
            "elements": [
                "botania:altgrass@1"
            ]
        },
        {
            "x": 0,
            "y": 3,
            "z": 2,
            "elements": [
                "gugu-utils:sparkmanahatch@1"
            ]
        },
        {
            "x": 0,
            "y": 1,
            "z": 1,
            "elements": [
                "botania:altgrass@1"
            ]
        },
        {
            "x": 1,
            "y": 3,
            "z": 2,
            "elements": [
                "gugu-utils:sparkmanahatch@1"
            ]
        },
        {
            "x": 1,
            "y": 1,
            "z": 1,
            "elements": [
                "botania:altgrass@1"
            ]
        },
        {
            "x": 2,
            "y": 1,
            "z": 1,
            "elements": [
                "botania:storage@3"
            ]
        },
        {
            "x": -2,
            "y": -1,
            "z": 4,
            "elements": [
                "botania:storage@4"
            ]
        },
        {
            "x": -1,
            "y": -1,
            "z": 4,
            "elements": [
                "botania:storage@4"
            ]
        },
        {
            "x": 0,
            "y": -1,
            "z": 4,
            "elements": [
                "botania:storage@4"
            ]
        },
        {
            "x": 1,
            "y": -1,
            "z": 4,
            "elements": [
                "botania:storage@4"
            ]
        },
        {
            "x": 2,
            "y": -1,
            "z": 4,
            "elements": [
                "botania:storage@4"
            ]
        },
        {
            "x": -2,
            "y": 2,
            "z": 1,
            "elements": [
                "gugu-utils:sparkmanahatch@1"
            ]
        },
        {
            "x": -1,
            "y": 2,
            "z": 1,
            "elements": [
                "botania:pool@3"
            ]
        },
        {
            "x": 0,
            "y": 2,
            "z": 1,
            "elements": [
                "botania:pool@3"
            ]
        }
    ]}