{
    "registryname": "ManaAuto",
	"localizedname": "自动化魔法",
	"requires-blueprint": true,
	"color": "E63CC4",
    "parts": [
        {
            "x": -1,
            "y": 0,
            "z": 0,
            "elements": "casings_all"
        },
        {
            "x": 0,
            "y": 0,
            "z": 0,
            "elements": [
                "modularmachinery:blockcontroller@2"
            ]
        },
        {
            "x": 1,
            "y": 2,
            "z": 1,
            "elements": [
                "botania:livingrock@0"
            ]
        },
        {
            "x": -2,
            "y": 0,
            "z": 0,
            "elements": "casings_all"
        },
        {
            "x": 1,
            "y": 0,
            "z": 0,
            "elements": "casings_all"
        },
        {
            "x": 2,
            "y": 2,
            "z": 1,
            "elements": [
                "modularmachinery:blockcasing@4"
            ]
        },
        {
            "x": 2,
            "y": 0,
            "z": 0,
            "elements": "casings_all"
        },
        {
            "x": -2,
            "y": 0,
            "z": 4,
            "elements": "casings_all"
        },
        {
            "x": -1,
            "y": 0,
            "z": 4,
            "elements": "casings_all"
        },
        {
            "x": 0,
            "y": 0,
            "z": 4,
            "elements": "casings_all"
        },
        {
            "x": 1,
            "y": 0,
            "z": 4,
            "elements": "casings_all"
        },
        {
            "x": 2,
            "y": 0,
            "z": 4,
            "elements": "casings_all"
        },
        {
            "x": 2,
            "y": -1,
            "z": 0,
            "elements": [
                "modularmachinery:blockcasing@4"
            ]
        },
        {
            "x": 1,
            "y": -1,
            "z": 0,
            "elements": [
                "modularmachinery:blockcasing@4"
            ]
        },
        {
            "x": -2,
            "y": 1,
            "z": 0,
            "elements": [
                "modularmachinery:blockcasing@4"
            ]
        },
        {
            "x": 0,
            "y": -1,
            "z": 0,
            "elements": [
                "modularmachinery:blockcasing@4"
            ]
        },
        {
            "x": -1,
            "y": 1,
            "z": 0,
            "elements": [
                "modularmachinery:blockcasing@4"
            ]
        },
        {
            "x": -1,
            "y": -1,
            "z": 0,
            "elements": [
                "modularmachinery:blockcasing@4"
            ]
        },
        {
            "x": 0,
            "y": 1,
            "z": 0,
            "elements": [
                "modularmachinery:blockcasing@4"
            ]
        },
        {
            "x": -2,
            "y": -1,
            "z": 0,
            "elements": [
                "modularmachinery:blockcasing@4"
            ]
        },
        {
            "x": 1,
            "y": 1,
            "z": 0,
            "elements": [
                "modularmachinery:blockcasing@4"
            ]
        },
        {
            "x": 2,
            "y": 1,
            "z": 0,
            "elements": [
                "modularmachinery:blockcasing@4"
            ]
        },
        {
            "x": -2,
            "y": 1,
            "z": 4,
            "elements": [
                "modularmachinery:blockcasing@4"
            ]
        },
        {
            "x": -2,
            "y": -1,
            "z": 3,
            "elements": [
                "modularmachinery:blockcasing@4"
            ]
        },
        {
            "x": -1,
            "y": 1,
            "z": 4,
            "elements": [
                "modularmachinery:blockcasing@4"
            ]
        },
        {
            "x": -1,
            "y": -1,
            "z": 3,
            "elements": [
                "minecraft:diamond_block@0"
            ]
        },
        {
            "x": 0,
            "y": 1,
            "z": 4,
            "elements": [
                "modularmachinery:blockcasing@4"
            ]
        },
        {
            "x": 0,
            "y": -1,
            "z": 3,
            "elements": [
                "additions:feng_ding-windkuai@0"
            ]
        },
        {
            "x": 1,
            "y": 1,
            "z": 4,
            "elements": [
                "modularmachinery:blockcasing@4"
            ]
        },
        {
            "x": 1,
            "y": -1,
            "z": 3,
            "elements": [
                "minecraft:diamond_block@0"
            ]
        },
        {
            "x": 2,
            "y": 1,
            "z": 4,
            "elements": [
                "modularmachinery:blockcasing@4"
            ]
        },
        {
            "x": 2,
            "y": -1,
            "z": 3,
            "elements": [
                "modularmachinery:blockcasing@4"
            ]
        },
        {
            "x": -2,
            "y": 2,
            "z": 0,
            "elements": [
                "gugu-utils:sparkmanahatch@0"
            ]
        },
        {
            "x": -1,
            "y": 2,
            "z": 0,
            "elements": [
                "modularmachinery:blockcasing@4"
            ]
        },
        {
            "x": 0,
            "y": 2,
            "z": 0,
            "elements": [
                "modularmachinery:blockcasing@4"
            ]
        },
        {
            "x": 1,
            "y": 2,
            "z": 0,
            "elements": [
                "modularmachinery:blockcasing@4"
            ]
        },
        {
            "x": 2,
            "y": 2,
            "z": 0,
            "elements": [
                "modularmachinery:blockcasing@4"
            ]
        },
        {
            "x": -2,
            "y": 2,
            "z": 4,
            "elements": [
                "gugu-utils:sparkmanahatch@0"
            ]
        },
        {
            "x": -2,
            "y": 0,
            "z": 3,
            "elements": "casings_all"
        },
        {
            "x": -1,
            "y": 2,
            "z": 4,
            "elements": [
                "modularmachinery:blockcasing@4"
            ]
        },
        {
            "x": -1,
            "y": 0,
            "z": 3,
            "elements": [
                "draconicevolution:draconium_block@0"
            ]
        },
        {
            "x": 0,
            "y": 2,
            "z": 4,
            "elements": [
                "modularmachinery:blockcasing@4"
            ]
        },
        {
            "x": 0,
            "y": 0,
            "z": 3,
            "elements": [
                "draconicevolution:infused_obsidian@0"
            ]
        },
        {
            "x": 1,
            "y": 2,
            "z": 4,
            "elements": [
                "modularmachinery:blockcasing@4"
            ]
        },
        {
            "x": 1,
            "y": 0,
            "z": 3,
            "elements": [
                "draconicevolution:draconium_block@0"
            ]
        },
        {
            "x": 2,
            "y": 2,
            "z": 4,
            "elements": [
                "modularmachinery:blockcasing@4"
            ]
        },
        {
            "x": 2,
            "y": 0,
            "z": 3,
            "elements": "casings_all"
        },
        {
            "x": 0,
            "y": 3,
            "z": 0,
            "elements": [
                "botania:runealtar@0"
            ]
        },
        {
            "x": -2,
            "y": 1,
            "z": 3,
            "elements": [
                "modularmachinery:blockcasing@4"
            ]
        },
        {
            "x": -2,
            "y": -1,
            "z": 2,
            "elements": [
                "modularmachinery:blockcasing@4"
            ]
        },
        {
            "x": -1,
            "y": 1,
            "z": 3,
            "elements": [
                "thermalfoundation:storage_alloy@6"
            ]
        },
        {
            "x": -1,
            "y": -1,
            "z": 2,
            "elements": [
                "additions:feng_ding-windkuai@0"
            ]
        },
        {
            "x": 0,
            "y": 1,
            "z": 3,
            "elements": [
                "thermalfoundation:storage@8"
            ]
        },
        {
            "x": 0,
            "y": -1,
            "z": 2,
            "elements": [
                "botania:storage@1"
            ]
        },
        {
            "x": 1,
            "y": 1,
            "z": 3,
            "elements": [
                "thermalfoundation:storage_alloy@6"
            ]
        },
        {
            "x": 1,
            "y": -1,
            "z": 2,
            "elements": [
                "additions:feng_ding-windkuai@0"
            ]
        },
        {
            "x": 2,
            "y": 1,
            "z": 3,
            "elements": [
                "modularmachinery:blockcasing@4"
            ]
        },
        {
            "x": 2,
            "y": -1,
            "z": 2,
            "elements": [
                "modularmachinery:blockcasing@4"
            ]
        },
        {
            "x": -2,
            "y": 2,
            "z": 3,
            "elements": [
                "gugu-utils:sparkmanahatch@0"
            ]
        },
        {
            "x": -2,
            "y": 0,
            "z": 2,
            "elements": "casings_all"
        },
        {
            "x": -1,
            "y": 2,
            "z": 3,
            "elements": [
                "botania:livingrock@0"
            ]
        },
        {
            "x": -1,
            "y": 0,
            "z": 2,
            "elements": [
                "draconicevolution:infused_obsidian@0"
            ]
        },
        {
            "x": 0,
            "y": 2,
            "z": 3,
            "elements": [
                "minecraft:lapis_block@0"
            ]
        },
        {
            "x": 0,
            "y": 0,
            "z": 2,
            "elements": [
                "botania:storage@3"
            ]
        },
        {
            "x": 1,
            "y": 2,
            "z": 3,
            "elements": [
                "botania:livingrock@0"
            ]
        },
        {
            "x": 1,
            "y": 0,
            "z": 2,
            "elements": [
                "draconicevolution:infused_obsidian@0"
            ]
        },
        {
            "x": 2,
            "y": 2,
            "z": 3,
            "elements": [
                "modularmachinery:blockcasing@4"
            ]
        },
        {
            "x": 2,
            "y": 0,
            "z": 2,
            "elements": "casings_all"
        },
        {
            "x": -2,
            "y": 1,
            "z": 2,
            "elements": [
                "modularmachinery:blockcasing@4"
            ]
        },
        {
            "x": -2,
            "y": -1,
            "z": 1,
            "elements": [
                "modularmachinery:blockcasing@4"
            ]
        },
        {
            "x": -1,
            "y": 1,
            "z": 2,
            "elements": [
                "thermalfoundation:storage@8"
            ]
        },
        {
            "x": -1,
            "y": -1,
            "z": 1,
            "elements": [
                "minecraft:diamond_block@0"
            ]
        },
        {
            "x": 0,
            "y": 1,
            "z": 2,
            "elements": [
                "thermalfoundation:storage_alloy@7"
            ]
        },
        {
            "x": 0,
            "y": -1,
            "z": 1,
            "elements": [
                "additions:feng_ding-windkuai@0"
            ]
        },
        {
            "x": 1,
            "y": 1,
            "z": 2,
            "elements": [
                "thermalfoundation:storage@8"
            ]
        },
        {
            "x": 1,
            "y": -1,
            "z": 1,
            "elements": [
                "minecraft:diamond_block@0"
            ]
        },
        {
            "x": 2,
            "y": 1,
            "z": 2,
            "elements": [
                "modularmachinery:blockcasing@4"
            ]
        },
        {
            "x": 2,
            "y": -1,
            "z": 1,
            "elements": [
                "modularmachinery:blockcasing@4"
            ]
        },
        {
            "x": -2,
            "y": 2,
            "z": 2,
            "elements": [
                "gugu-utils:sparkmanahatch@0"
            ]
        },
        {
            "x": -2,
            "y": 0,
            "z": 1,
            "elements": "casings_all"
        },
        {
            "x": -1,
            "y": 2,
            "z": 2,
            "elements": [
                "minecraft:lapis_block@0"
            ]
        },
        {
            "x": -1,
            "y": 0,
            "z": 1,
            "elements": [
                "draconicevolution:draconium_block@0"
            ]
        },
        {
            "x": 0,
            "y": 2,
            "z": 2,
            "elements": [
                "botania:livingrock@0"
            ]
        },
        {
            "x": 0,
            "y": 0,
            "z": 1,
            "elements": [
                "draconicevolution:infused_obsidian@0"
            ]
        },
        {
            "x": 1,
            "y": 2,
            "z": 2,
            "elements": [
                "minecraft:lapis_block@0"
            ]
        },
        {
            "x": 1,
            "y": 0,
            "z": 1,
            "elements": [
                "draconicevolution:draconium_block@0"
            ]
        },
        {
            "x": 2,
            "y": 2,
            "z": 2,
            "elements": [
                "modularmachinery:blockcasing@4"
            ]
        },
        {
            "x": 2,
            "y": 0,
            "z": 1,
            "elements": "casings_all"
        },
        {
            "x": -2,
            "y": 1,
            "z": 1,
            "elements": [
                "modularmachinery:blockcasing@4"
            ]
        },
        {
            "x": -1,
            "y": 1,
            "z": 1,
            "elements": [
                "thermalfoundation:storage_alloy@6"
            ]
        },
        {
            "x": 0,
            "y": 3,
            "z": 2,
            "elements": [
                "botania:terraplate@0"
            ]
        },
        {
            "x": 0,
            "y": 1,
            "z": 1,
            "elements": [
                "thermalfoundation:storage@8"
            ]
        },
        {
            "x": 1,
            "y": 1,
            "z": 1,
            "elements": [
                "thermalfoundation:storage_alloy@6"
            ]
        },
        {
            "x": 2,
            "y": 1,
            "z": 1,
            "elements": [
                "modularmachinery:blockcasing@4"
            ]
        },
        {
            "x": -2,
            "y": -1,
            "z": 4,
            "elements": [
                "modularmachinery:blockcasing@4"
            ]
        },
        {
            "x": -1,
            "y": -1,
            "z": 4,
            "elements": [
                "modularmachinery:blockcasing@4"
            ]
        },
        {
            "x": 0,
            "y": -1,
            "z": 4,
            "elements": [
                "modularmachinery:blockcasing@4"
            ]
        },
        {
            "x": 1,
            "y": -1,
            "z": 4,
            "elements": [
                "modularmachinery:blockcasing@4"
            ]
        },
        {
            "x": 2,
            "y": -1,
            "z": 4,
            "elements": [
                "modularmachinery:blockcasing@4"
            ]
        },
        {
            "x": -2,
            "y": 2,
            "z": 1,
            "elements": [
                "gugu-utils:sparkmanahatch@0"
            ]
        },
        {
            "x": -1,
            "y": 2,
            "z": 1,
            "elements": [
                "botania:livingrock@0"
            ]
        },
        {
            "x": 0,
            "y": 2,
            "z": 1,
            "elements": [
                "minecraft:lapis_block@0"
            ]
        }
    ]}